{
 "cells": [
  {
   "cell_type": "code",
   "execution_count": 24,
   "metadata": {},
   "outputs": [],
   "source": [
    "import json\n",
    "\n",
    "import boto3\n",
    "import sagemaker\n"
   ]
  },
  {
   "cell_type": "markdown",
   "metadata": {},
   "source": [
    "# Code run elsewhere: \n",
    "\n",
    "The following code was run: \n",
    "\n",
    "\n",
    "```python\n",
    "IAM_ROLE = \"arn:aws:iam::220582896887:role/programmatic-aws-sagemaker-role-access\"\n",
    "\n",
    "model_data = Estimator.attach(\n",
    "    training_job_name=\"1940a1b\",\n",
    "    sagemaker_session=SESSION\n",
    ").model_data\n",
    "\n",
    "model = Model(\n",
    "    image_uri=\"763104351884.dkr.ecr.us-east-1.amazonaws.com/pytorch-inference:2.1.0-cpu-py310-ubuntu20.04-sagemaker\",\n",
    "    model_data=model_data,\n",
    "    role=IAM_ROLE,\n",
    "    sagemaker_session=SESSION,\n",
    "    source_dir=\"./\",\n",
    "    entry_point=\"src/mnist_sagemaker_ci_cd/lib/inference.py\",\n",
    "    dependencies=[\"src/mnist_sagemaker_ci_cd/deps/fit/requirements.txt\"],\n",
    ")\n",
    "\n",
    "endpoint_name = \"1940a1b-predictor\"\n",
    "predictor = model.deploy(\n",
    "    initial_instance_count=1,\n",
    "    instance_type=\"ml.m5.large\",\n",
    "    endpoint_name=endpoint_name,\n",
    ")\n",
    "```"
   ]
  },
  {
   "cell_type": "code",
   "execution_count": 26,
   "metadata": {},
   "outputs": [
    {
     "ename": "ModelError",
     "evalue": "An error occurred (ModelError) when calling the InvokeEndpoint operation: Received server error (0) from primary with message \"Your invocation timed out while waiting for a response from container primary. Review the latency metrics for each container in Amazon CloudWatch, resolve the issue, and try again.\". See https://us-east-1.console.aws.amazon.com/cloudwatch/home?region=us-east-1#logEventViewer:group=/aws/sagemaker/Endpoints/1940a1b-predictor in account 220582896887 for more information.",
     "output_type": "error",
     "traceback": [
      "\u001b[0;31m---------------------------------------------------------------------------\u001b[0m",
      "\u001b[0;31mModelError\u001b[0m                                Traceback (most recent call last)",
      "Cell \u001b[0;32mIn[26], line 6\u001b[0m\n\u001b[1;32m      4\u001b[0m ENDPOINT_NAME \u001b[38;5;241m=\u001b[39m \u001b[38;5;124m\"\u001b[39m\u001b[38;5;124m1940a1b-predictor\u001b[39m\u001b[38;5;124m\"\u001b[39m\n\u001b[1;32m      5\u001b[0m CLIENT \u001b[38;5;241m=\u001b[39m SESSION\u001b[38;5;241m.\u001b[39msagemaker_runtime_client\n\u001b[0;32m----> 6\u001b[0m response \u001b[38;5;241m=\u001b[39m \u001b[43mCLIENT\u001b[49m\u001b[38;5;241;43m.\u001b[39;49m\u001b[43minvoke_endpoint\u001b[49m\u001b[43m(\u001b[49m\n\u001b[1;32m      7\u001b[0m \u001b[43m    \u001b[49m\u001b[43mEndpointName\u001b[49m\u001b[38;5;241;43m=\u001b[39;49m\u001b[43mENDPOINT_NAME\u001b[49m\u001b[43m,\u001b[49m\n\u001b[1;32m      8\u001b[0m \u001b[43m    \u001b[49m\u001b[43mContentType\u001b[49m\u001b[38;5;241;43m=\u001b[39;49m\u001b[38;5;124;43m\"\u001b[39;49m\u001b[38;5;124;43mapplication/json\u001b[39;49m\u001b[38;5;124;43m\"\u001b[39;49m\u001b[43m,\u001b[49m\n\u001b[1;32m      9\u001b[0m \u001b[43m    \u001b[49m\u001b[43mBody\u001b[49m\u001b[38;5;241;43m=\u001b[39;49m\u001b[43mjson\u001b[49m\u001b[38;5;241;43m.\u001b[39;49m\u001b[43mdumps\u001b[49m\u001b[43m(\u001b[49m\u001b[43m[\u001b[49m\u001b[38;5;124;43m\"\u001b[39;49m\u001b[38;5;124;43mDo you like Toyota Corolla?\u001b[39;49m\u001b[38;5;124;43m\"\u001b[39;49m\u001b[43m,\u001b[49m\u001b[43m \u001b[49m\u001b[38;5;124;43m\"\u001b[39;49m\u001b[38;5;124;43mI have a Nissan\u001b[39;49m\u001b[38;5;124;43m\"\u001b[39;49m\u001b[43m]\u001b[49m\u001b[43m)\u001b[49m\u001b[43m,\u001b[49m\n\u001b[1;32m     10\u001b[0m \u001b[43m)\u001b[49m\n",
      "File \u001b[0;32m/opt/mnist-sagemaker-ci-cd-env/lib/python3.11/site-packages/botocore/client.py:553\u001b[0m, in \u001b[0;36mClientCreator._create_api_method.<locals>._api_call\u001b[0;34m(self, *args, **kwargs)\u001b[0m\n\u001b[1;32m    549\u001b[0m     \u001b[38;5;28;01mraise\u001b[39;00m \u001b[38;5;167;01mTypeError\u001b[39;00m(\n\u001b[1;32m    550\u001b[0m         \u001b[38;5;124mf\u001b[39m\u001b[38;5;124m\"\u001b[39m\u001b[38;5;132;01m{\u001b[39;00mpy_operation_name\u001b[38;5;132;01m}\u001b[39;00m\u001b[38;5;124m() only accepts keyword arguments.\u001b[39m\u001b[38;5;124m\"\u001b[39m\n\u001b[1;32m    551\u001b[0m     )\n\u001b[1;32m    552\u001b[0m \u001b[38;5;66;03m# The \"self\" in this scope is referring to the BaseClient.\u001b[39;00m\n\u001b[0;32m--> 553\u001b[0m \u001b[38;5;28;01mreturn\u001b[39;00m \u001b[38;5;28;43mself\u001b[39;49m\u001b[38;5;241;43m.\u001b[39;49m\u001b[43m_make_api_call\u001b[49m\u001b[43m(\u001b[49m\u001b[43moperation_name\u001b[49m\u001b[43m,\u001b[49m\u001b[43m \u001b[49m\u001b[43mkwargs\u001b[49m\u001b[43m)\u001b[49m\n",
      "File \u001b[0;32m/opt/mnist-sagemaker-ci-cd-env/lib/python3.11/site-packages/botocore/client.py:1009\u001b[0m, in \u001b[0;36mBaseClient._make_api_call\u001b[0;34m(self, operation_name, api_params)\u001b[0m\n\u001b[1;32m   1005\u001b[0m     error_code \u001b[38;5;241m=\u001b[39m error_info\u001b[38;5;241m.\u001b[39mget(\u001b[38;5;124m\"\u001b[39m\u001b[38;5;124mQueryErrorCode\u001b[39m\u001b[38;5;124m\"\u001b[39m) \u001b[38;5;129;01mor\u001b[39;00m error_info\u001b[38;5;241m.\u001b[39mget(\n\u001b[1;32m   1006\u001b[0m         \u001b[38;5;124m\"\u001b[39m\u001b[38;5;124mCode\u001b[39m\u001b[38;5;124m\"\u001b[39m\n\u001b[1;32m   1007\u001b[0m     )\n\u001b[1;32m   1008\u001b[0m     error_class \u001b[38;5;241m=\u001b[39m \u001b[38;5;28mself\u001b[39m\u001b[38;5;241m.\u001b[39mexceptions\u001b[38;5;241m.\u001b[39mfrom_code(error_code)\n\u001b[0;32m-> 1009\u001b[0m     \u001b[38;5;28;01mraise\u001b[39;00m error_class(parsed_response, operation_name)\n\u001b[1;32m   1010\u001b[0m \u001b[38;5;28;01melse\u001b[39;00m:\n\u001b[1;32m   1011\u001b[0m     \u001b[38;5;28;01mreturn\u001b[39;00m parsed_response\n",
      "\u001b[0;31mModelError\u001b[0m: An error occurred (ModelError) when calling the InvokeEndpoint operation: Received server error (0) from primary with message \"Your invocation timed out while waiting for a response from container primary. Review the latency metrics for each container in Amazon CloudWatch, resolve the issue, and try again.\". See https://us-east-1.console.aws.amazon.com/cloudwatch/home?region=us-east-1#logEventViewer:group=/aws/sagemaker/Endpoints/1940a1b-predictor in account 220582896887 for more information."
     ]
    }
   ],
   "source": [
    "SESSION = sagemaker.Session(\n",
    "        boto3.Session(region_name=\"us-east-1\")\n",
    "    )\n",
    "ENDPOINT_NAME = \"1940a1b-predictor\"\n",
    "CLIENT = SESSION.sagemaker_runtime_client\n",
    "response = CLIENT.invoke_endpoint(\n",
    "    EndpointName=ENDPOINT_NAME,\n",
    "    ContentType=\"application/json\",\n",
    "    Body=json.dumps([\"Do you like Toyota Corolla?\", \"I have a Nissan\"]),\n",
    ")\n"
   ]
  },
  {
   "cell_type": "code",
   "execution_count": 27,
   "metadata": {},
   "outputs": [
    {
     "ename": "NameError",
     "evalue": "name 'response' is not defined",
     "output_type": "error",
     "traceback": [
      "\u001b[0;31m---------------------------------------------------------------------------\u001b[0m",
      "\u001b[0;31mNameError\u001b[0m                                 Traceback (most recent call last)",
      "Cell \u001b[0;32mIn[27], line 1\u001b[0m\n\u001b[0;32m----> 1\u001b[0m r \u001b[38;5;241m=\u001b[39m \u001b[43mresponse\u001b[49m[\u001b[38;5;124m\"\u001b[39m\u001b[38;5;124mBody\u001b[39m\u001b[38;5;124m\"\u001b[39m]\n\u001b[1;32m      2\u001b[0m \u001b[38;5;28mprint\u001b[39m(\u001b[38;5;124m\"\u001b[39m\u001b[38;5;124mRESULT r.read().decode():\u001b[39m\u001b[38;5;124m\"\u001b[39m, r\u001b[38;5;241m.\u001b[39mread()\u001b[38;5;241m.\u001b[39mdecode())\n",
      "\u001b[0;31mNameError\u001b[0m: name 'response' is not defined"
     ]
    }
   ],
   "source": [
    "r = response[\"Body\"]\n",
    "print(\"RESULT r.read().decode():\", r.read().decode())"
   ]
  }
 ],
 "metadata": {
  "kernelspec": {
   "display_name": "mnist-sagemaker-ci-cd-env",
   "language": "python",
   "name": "python3"
  },
  "language_info": {
   "codemirror_mode": {
    "name": "ipython",
    "version": 3
   },
   "file_extension": ".py",
   "mimetype": "text/x-python",
   "name": "python",
   "nbconvert_exporter": "python",
   "pygments_lexer": "ipython3",
   "version": "3.11.7"
  }
 },
 "nbformat": 4,
 "nbformat_minor": 2
}
